Workbook

Sheet README
B2: 🧴 Moisturisers — Formula-Driven Interactive Dashboard
B3: Retention & category intelligence · Jan 2024 – Jun 2026 · works entirely with native Excel formulas (no macros)
B5: HOW TO USE WITH YOUR FULL RAW DUMP (155,537 orders)
B6: 1. Open the DATA sheet. Row 1 holds the exact column headers of your raw journey dump.
B7: 2. Select cell A2 and paste your whole dump over the sample rows (all 35 columns, any number of rows).
B8: 3. The grey helper columns (AJ onwards) auto-fill for pasted rows because DATA is an Excel Table.
B9: If they ever stop at the old row count: click the last filled helper cell, copy (Ctrl+C),
B10: select down to your last data row (Ctrl+Shift+End on the helper columns), and paste (Ctrl+V).
B11: 4. Press F9 to recalculate (first full recalc on 155k rows can take a minute or two).
B12: 5. Everything else updates by itself: DASHBOARD tiles, CONCLUSIONS text, VARIANTS and GRAMMAGE tables.
B14: WHAT EACH SHEET DOES
B15: DASHBOARD — the interactive mockup: dropdown filters (Category, Variant SKU, From/To month, Journey Depth, Geo region)
... B31: · Seasonality strength: Highly ≥40% of orders in peak season · Moderately 30–40% · Evergreen <30%.

Sheet DASHBOARD
B2: 🧴 NAT HABIT — RETENTION DASHBOARD
B3: Dropdown filters drive every tile below (cohort = customers whose FIRST order matches)
B4: Category | C4: All
B6: Variant (SKU) | C6: All
B8: From month | C8: All
B10: To month | C10: All
B12: Journey depth | C12: All
B14: Geo region | C14: All
B17: COHORT
B18: Customers in cohort | C18: =COUNTIFS(DATA!$CZ:$CZ,1)
B19: Total orders | C19: =SUMIFS(DATA!$AH:$AH,DATA!$CZ:$CZ,1)
B20: Repeat buyers | C20: =COUNTIFS(DATA!$CZ:$CZ,1,DATA!$AI:$AI,1)
B21: Repeat rate | C21: =IFERROR(C20/C18,"")
B23: SEASONALITY (orders by variant's intended season line)
B24: Cold Winter (Dec–Feb) variants | C24: =COUNTIFS(DATA!$CZ:$CZ,1,DATA!$AS:$AS,"Cold Winter")+COUNTIFS(DATA!$CZ:$CZ,1,DATA!$BB:$BB,"Cold Winter")+COUNTIFS(DATA!$CZ:$CZ,1,DATA!$BK:$BK,"Cold Winter")+COUNTIFS(DATA!$CZ:$CZ,1,DATA!$BT:$BT,"Cold Winter")+COUNTIFS(DATA!$CZ:$CZ,1,DATA!$CC:$CC,"Cold Winter")+COUNTIFS(DATA!$CZ:$CZ,1,DATA!$CL:$CL,"Cold Winter")
B25: Hot Dry (Mar–May) variants | C25: =COUNTIFS(DATA!$CZ:$CZ,1,DATA!$AS:$AS,"Hot Dry")+COUNTIFS(DATA!$CZ:$CZ,1,DATA!$BB:$BB,"Hot Dry")+COUNTIFS(DATA!$CZ:$CZ,1,DATA!$BK:$BK,"Hot Dry")+COUNTIFS(DATA!$CZ:$CZ,1,DATA!$BT:$BT,"Hot Dry")+COUNTIFS(DATA!$CZ:$CZ,1,DATA!$CC:$CC,"Hot Dry")+COUNTIFS(DATA!$CZ:$CZ,1,DATA!$CL:$CL,"Hot Dry")
B26: Hot Humid (Jun–Sep) variants | C26: =COUNTIFS(DATA!$CZ:$CZ,1,DATA!$AS:$AS,"Hot Humid")+COUNTIFS(DATA!$CZ:$CZ,1,DATA!$BB:$BB,"Hot Humid")+COUNTIFS(DATA!$CZ:$CZ,1,DATA!$BK:$BK,"Hot Humid")+COUNTIFS(DATA!$CZ:$CZ,1,DATA!$BT:$BT,"Hot Humid")+COUNTIFS(DATA!$CZ:$CZ,1,DATA!$CC:$CC,"Hot Humid")+COUNTIFS(DATA!$CZ:$CZ,1,DATA!$CL:$CL,"Hot Humid")
B27: Non-Seasonal / Concern variants | C27: =COUNTIFS(DATA!$CZ:$CZ,1,DATA!$AS:$AS,"Non-Seasonal")+COUNTIFS(DATA!$CZ:$CZ,1,DATA!$BB:$BB,"Non-Seasonal")+COUNTIFS(DATA!$CZ:$CZ,1,DATA!$BK:$BK,"Non-Seasonal")+COUNTIFS(DATA!$CZ:$CZ,1,DATA!$BT:$BT,"Non-Seasonal")+COUNTIFS(DATA!$CZ:$CZ,1,DATA!$CC:$CC,"Non-Seasonal")+COUNTIFS(DATA!$CZ:$CZ,1,DATA!$CL:$CL,"Non-Seasonal")
B28: Peak Season | C28: =IF(SUM(C24:C27)=0,"—",INDEX({"Cold Winter";"Hot Dry";"Hot Humid";"Non-Seasonal"},MATCH(MAX(C24:C27),C24:C27,0)))
B29: Purchase timing (calendar month buckets): | C29: =COUNTIFS(DATA!$CZ:$CZ,1,DATA!$AR:$AR,"Cold Winter")+COUNTIFS(DATA!$CZ:$CZ,1,DATA!$BA:$BA,"Cold Winter")+COUNTIFS(DATA!$CZ:$CZ,1,DATA!$BJ:$BJ,"Cold Winter")+COUNTIFS(DATA!$CZ:$CZ,1,DATA!$BS:$BS,"Cold Winter")+COUNTIFS(DATA!$CZ:$CZ,1,DATA!$CB:$CB,"Cold Winter")+COUNTIFS(DATA!$CZ:$CZ,1,DATA!$CK:$CK,"Cold Winter") | D29: =COUNTIFS(DATA!$CZ:$CZ,1,DATA!$AR:$AR,"Hot Dry")+COUNTIFS(DATA!$CZ:$CZ,1,DATA!$BA:$BA,"Hot Dry")+COUNTIFS(DATA!$CZ:$CZ,1,DATA!$BJ:$BJ,"Hot Dry")+COUNTIFS(DATA!$CZ:$CZ,1,DATA!$BS:$BS,"Hot Dry")+COUNTIFS(DATA!$CZ:$CZ,1,DATA!$CB:$CB,"Hot Dry")+COUNTIFS(DATA!$CZ:$CZ,1,DATA!$CK:$CK,"Hot Dry") | E29: =COUNTIFS(DATA!$CZ:$CZ,1,DATA!$AR:$AR,"Hot Humid")+COUNTIFS(DATA!$CZ:$CZ,1,DATA!$BA:$BA,"Hot Humid")+COUNTIFS(DATA!$CZ:$CZ,1,DATA!$BJ:$BJ,"Hot Humid")+COUNTIFS(DATA!$CZ:$CZ,1,DATA!$BS:$BS,"Hot Humid")+COUNTIFS(DATA!$CZ:$CZ,1,DATA!$CB:$CB,"Hot Humid")+COUNTIFS(DATA!$CZ:$CZ,1,DATA!$CK:$CK,"Hot Humid") | F29: =COUNTIFS(DATA!$CZ:$CZ,1,DATA!$AR:$AR,"Post-Monsoon")+COUNTIFS(DATA!$CZ:$CZ,1,DATA!$BA:$BA,"Post-Monsoon")+COUNTIFS(DATA!$CZ:$CZ,1,DATA!$BJ:$BJ,"Post-Monsoon")+COUNTIFS(DATA!$CZ:$CZ,1,DATA!$BS:$BS,"Post-Monsoon")+COUNTIFS(DATA!$CZ:$CZ,1,DATA!$CB:$CB,"Post-Monsoon")+COUNTIFS(DATA!$CZ:$CZ,1,DATA!$CK:$CK,"Post-Monsoon")
C30: Cold Winter | D30: Hot Dry | E30: Hot Humid | F30: Post-Monsoon
B32: GELS & TOTALS
B33: Active Gel Count | C33: =COUNTIFS(DATA!$CZ:$CZ,1,DATA!$AN:$AN,"Active Gel")+COUNTIFS(DATA!$CZ:$CZ,1,DATA!$AW:$AW,"Active Gel")+COUNTIFS(DATA!$CZ:$CZ,1,DATA!$BF:$BF,"Active Gel")+COUNTIFS(DATA!$CZ:$CZ,1,DATA!$BO:$BO,"Active Gel")+COUNTIFS(DATA!$CZ:$CZ,1,DATA!$BX:$BX,"Active Gel")+COUNTIFS(DATA!$CZ:$CZ,1,DATA!$CG:$CG,"Active Gel")
B34: Aloevera Gel Count | C34: =COUNTIFS(DATA!$CZ:$CZ,1,DATA!$AN:$AN,"Aloe Vera Gel")+COUNTIFS(DATA!$CZ:$CZ,1,DATA!$AW:$AW,"Aloe Vera Gel")+COUNTIFS(DATA!$CZ:$CZ,1,DATA!$BF:$BF,"Aloe Vera Gel")+COUNTIFS(DATA!$CZ:$CZ,1,DATA!$BO:$BO,"Aloe Vera Gel")+COUNTIFS(DATA!$CZ:$CZ,1,DATA!$BX:$BX,"Aloe Vera Gel")+COUNTIFS(DATA!$CZ:$CZ,1,DATA!$CG:$CG,"Aloe Vera Gel")
B35: Face Malai Count | C35: =COUNTIFS(DATA!$CZ:$CZ,1,DATA!$AN:$AN,"Face Malai")+COUNTIFS(DATA!$CZ:$CZ,1,DATA!$AW:$AW,"Face Malai")+COUNTIFS(DATA!$CZ:$CZ,1,DATA!$BF:$BF,"Face Malai")+COUNTIFS(DATA!$CZ:$CZ,1,DATA!$BO:$BO,"Face Malai")+COUNTIFS(DATA!$CZ:$CZ,1,DATA!$BX:$BX,"Face Malai")+COUNTIFS(DATA!$CZ:$CZ,1,DATA!$CG:$CG,"Face Malai")
B36: Total Orders | C36: =SUMIFS(DATA!$AH:$AH,DATA!$CZ:$CZ,1)
B38: LOYALTY & JOURNEY
B39: Repeat customers (2+ orders) | C39: =COUNTIFS(DATA!$CZ:$CZ,1,DATA!$CQ:$CQ,1)
B40: V2V Loyalty % | C40: =IFERROR(COUNTIFS(DATA!$CZ:$CZ,1,DATA!$CQ:$CQ,1,DATA!$CX:$CX,1)/C39,"")
B41: V2C Loyalty % | C41: =IFERROR(COUNTIFS(DATA!$CZ:$CZ,1,DATA!$CQ:$CQ,1,DATA!$CY:$CY,1)/C39,"")
B42: Avg Purchase Days V2V | C42: =IFERROR(AVERAGEIFS(DATA!$CW:$CW,DATA!$CZ:$CZ,1,DATA!$CX:$CX,1),"")
B43: Avg Purchase Days V2C | C43: =IFERROR(AVERAGEIFS(DATA!$CW:$CW,DATA!$CZ:$CZ,1,DATA!$CY:$CY,1),"")
B44: Avg Order Count V2V | C44: =IFERROR(AVERAGEIFS(DATA!$AH:$AH,DATA!$CZ:$CZ,1,DATA!$CX:$CX,1),"")
B45: Avg Order Count V2C | C45: =IFERROR(AVERAGEIFS(DATA!$AH:$AH,DATA!$CZ:$CZ,1,DATA!$CY:$CY,1),"")

Sheet CONCLUSIONS
B1: FORMULA-DRIVEN CONCLUSIONS — whole workbook level
B2: Every number is computed and every verdict is a formula branch; they update as soon as DATA changes.
B4: Is Face Malai Seasonal? | C4: =IF(COUNTIF(VARIANTS!$K$3:$K$21,"Highly Seasonal")=0,IF(COUNTIF(VARIANTS!$K$3:$K$21,"Evergreen")>0,"NO — Mostly evergreen with "&COUNTIF(VARIANTS!$K$3:$K$21,"Evergreen")&" evergreen variants","MIXED"),IF(COUNTIF(VARIANTS!$K$3:$K$21,"Highly Seasonal")>=COUNTIF(VARIANTS!$K$3:$K$21,"Evergreen"),"YES — "&COUNTIF(VARIANTS!$K$3:$K$21,"Highly Seasonal")&" of "&COUNTIF(VARIANTS!$I$3:$I$21,"<>Gel")&" Face Malai variants are highly seasonal","MIXED — "&COUNTIF(VARIANTS!$K$3:$K$21,"Highly Seasonal")&" highly seasonal vs "&COUNTIF(VARIANTS!$K$3:$K$21,"Evergreen")&" evergreen variants"))
B5: Overall Repeat Behaviour | C5: =IFERROR(TEXT(GRAMMAGE!D9/GRAMMAGE!C9,"0%")&" of all face moisturiser transitions are same product repeats ("&TEXT(GRAMMAGE!D9,"#,##0")&" of "&TEXT(GRAMMAGE!C9,"#,##0")&" transitions). "&IF(GRAMMAGE!D9/GRAMMAGE!C9>=0.6,"STRONG",IF(GRAMMAGE!D9/GRAMMAGE!C9>=0.45,"MODERATE","WEAK"))&" — switching behaviour exists across sizes and formats.","")
B6: 30g → 50g Conversion (FM Only) | C6: ="Out of "&TEXT(GRAMMAGE!C4,"#,##0")&" FM 30g transitions — "&TEXT(GRAMMAGE!L4,"#,##0")&" ("&TEXT(IFERROR(GRAMMAGE!L4/GRAMMAGE!C4,0),"0%")&") moved to FM 50g. "&IF(GRAMMAGE!L4>=GRAMMAGE!M4,"This is the primary internal upsize path.","Secondary — the cross-category gel switch is bigger.")
B7: 30g → Active Gel (Cross-Category Upsize) | C7: ="Out of "&TEXT(GRAMMAGE!C4,"#,##0")&" FM 30g transitions — "&TEXT(GRAMMAGE!M4,"#,##0")&" ("&TEXT(IFERROR(GRAMMAGE!M4/GRAMMAGE!C4,0),"0%")&") moved to Active Gel 50g. "&IF(GRAMMAGE!M4>GRAMMAGE!L4,"More 30g buyers move to Active Gel than FM 50g — gel format has stronger pull than size upgrade within FM.","FM 50g currently converts better than the gel switch.")
B8: Downsize Risk Assessment | C8: ="DOWNSIZE ALERT: "&TEXT(IFERROR(GRAMMAGE!N5/GRAMMAGE!C5,0),"0%")&" of FM 50g buyers drop to 30g ("&TEXT(GRAMMAGE!N5,"#,##0")&" transitions). AND "&TEXT(IFERROR(GRAMMAGE!O6/GRAMMAGE!C6,0),"0%")&" of Active Gel buyers also drop to FM 30g ("&TEXT(GRAMMAGE!O6,"#,##0")&" transitions). "&IF(OR(IFERROR(GRAMMAGE!N5/GRAMMAGE!C5,0)>=0.2,IFERROR(GRAMMAGE!O6/GRAMMAGE!C6,0)>=0.2),"Portfolio-wide downsize pressure detected.","Downsize pressure within tolerance.")
B9: Key Business Recommendation | C9: =IF(GRAMMAGE!M4>GRAMMAGE!L4,"FOCUS: 30g buyers prefer switching to Active Gel over FM 50g. Bundle strategy: FM 30g + Active Gel 50g trial kit could accelerate this natural behaviour.","FOCUS: strengthen the FM 30g → FM 50g upsize path ("&TEXT(IFERROR(GRAMMAGE!L4/GRAMMAGE!C4,0),"0%")&" today). Consider 50g refill pricing or a size-up nudge at reorder.")

Sheet VARIANTS
A1: VARIANT SUMMARY — whole workbook (ignores dashboard filters)
A2: Variant | B2: Cold Winter | C2: Hot Dry | D2: Hot Humid | E2: Post-Monsoon | F2: Total Orders | G2: Peak Season | H2: Peak Share | I2: Intended Season | J2: Season Match? | K2: Seasonality Strength | L2: Entry Users | M2: Bought Once | N2: Repeat Rate | O2: Avg Days 1→2
A3: Flax Walnut | B3: =COUNTIFS(DATA!$AO:$AO,$A3,DATA!$AR:$AR,"Cold Winter")+COUNTIFS(DATA!$AX:$AX,$A3,DATA!$BA:$BA,"Cold Winter")+COUNTIFS(DATA!$BG:$BG,$A3,DATA!$BJ:$BJ,"Cold Winter")+COUNTIFS(DATA!$BP:$BP,$A3,DATA!$BS:$BS,"Cold Winter")+COUNTIFS(DATA!$BY:$BY,$A3,DATA!$CB:$CB,"Cold Winter")+COUNTIFS(DATA!$CH:$CH,$A3,DATA!$CK:$CK,"Cold Winter") | C3: =COUNTIFS(DATA!$AO:$AO,$A3,DATA!$AR:$AR,"Hot Dry")+COUNTIFS(DATA!$AX:$AX,$A3,DATA!$BA:$BA,"Hot Dry")+COUNTIFS(DATA!$BG:$BG,$A3,DATA!$BJ:$BJ,"Hot Dry")+COUNTIFS(DATA!$BP:$BP,$A3,DATA!$BS:$BS,"Hot Dry")+COUNTIFS(DATA!$BY:$BY,$A3,DATA!$CB:$CB,"Hot Dry")+COUNTIFS(DATA!$CH:$CH,$A3,DATA!$CK:$CK,"Hot Dry") | D3: =COUNTIFS(DATA!$AO:$AO,$A3,DATA!$AR:$AR,"Hot Humid")+COUNTIFS(DATA!$AX:$AX,$A3,DATA!$BA:$BA,"Hot Humid")+COUNTIFS(DATA!$BG:$BG,$A3,DATA!$BJ:$BJ,"Hot Humid")+COUNTIFS(DATA!$BP:$BP,$A3,DATA!$BS:$BS,"Hot Humid")+COUNTIFS(DATA!$BY:$BY,$A3,DATA!$CB:$CB,"Hot Humid")+COUNTIFS(DATA!$CH:$CH,$A3,DATA!$CK:$CK,"Hot Humid") | E3: =COUNTIFS(DATA!$AO:$AO,$A3,DATA!$AR:$AR,"Post-Monsoon")+COUNTIFS(DATA!$AX:$AX,$A3,DATA!$BA:$BA,"Post-Monsoon")+COUNTIFS(DATA!$BG:$BG,$A3,DATA!$BJ:$BJ,"Post-Monsoon")+COUNTIFS(DATA!$BP:$BP,$A3,DATA!$BS:$BS,"Post-Monsoon")+COUNTIFS(DATA!$BY:$BY,$A3,DATA!$CB:$CB,"Post-Monsoon")+COUNTIFS(DATA!$CH:$CH,$A3,DATA!$CK:$CK,"Post-Monsoon") | F3: =SUM(B3:E3) | G3: =IF(F3=0,"—",INDEX({"Cold Winter";"Hot Dry";"Hot Humid";"Post-Monsoon"},MATCH(MAX(B3:E3),B3:E3,0))) | H3: =IFERROR(MAX(B3:E3)/F3,"") | I3: =IFERROR(VLOOKUP($A3,DECODE!$K$3:$L$21,2,FALSE),"") | J3: =IF(OR(I3="Non-Seasonal",I3="Gel"),"—",IF(G3=I3,"Matches","No Match")) | K3: =IF(J3="—",IF(I3="Gel","—","Evergreen"),IF(H3>=0.4,"Highly Seasonal",IF(H3>=0.3,"Moderately Seasonal","Evergreen"))) | L3: =COUNTIFS(DATA!$AO:$AO,$A3) | M3: =COUNTIFS(DATA!$AO:$AO,$A3,DATA!$AH:$AH,1) | N3: =IFERROR(1-M3/L3,"") | O3: =IFERROR(AVERAGEIFS(DATA!$CW:$CW,DATA!$CN:$CN,$A3),"")
A4: Tomato Patchouli | B4: =COUNTIFS(DATA!$AO:$AO,$A4,DATA!$AR:$AR,"Cold Winter")+COUNTIFS(DATA!$AX:$AX,$A4,DATA!$BA:$BA,"Cold Winter")+COUNTIFS(DATA!$BG:$BG,$A4,DATA!$BJ:$BJ,"Cold Winter")+COUNTIFS(DATA!$BP:$BP,$A4,DATA!$BS:$BS,"Cold Winter")+COUNTIFS(DATA!$BY:$BY,$A4,DATA!$CB:$CB,"Cold Winter")+COUNTIFS(DATA!$CH:$CH,$A4,DATA!$CK:$CK,"Cold Winter") | C4: =COUNTIFS(DATA!$AO:$AO,$A4,DATA!$AR:$AR,"Hot Dry")+COUNTIFS(DATA!$AX:$AX,$A4,DATA!$BA:$BA,"Hot Dry")+COUNTIFS(DATA!$BG:$BG,$A4,DATA!$BJ:$BJ,"Hot Dry")+COUNTIFS(DATA!$BP:$BP,$A4,DATA!$BS:$BS,"Hot Dry")+COUNTIFS(DATA!$BY:$BY,$A4,DATA!$CB:$CB,"Hot Dry")+COUNTIFS(DATA!$CH:$CH,$A4,DATA!$CK:$CK,"Hot Dry") | D4: =COUNTIFS(DATA!$AO:$AO,$A4,DATA!$AR:$AR,"Hot Humid")+COUNTIFS(DATA!$AX:$AX,$A4,DATA!$BA:$BA,"Hot Humid")+COUNTIFS(DATA!$BG:$BG,$A4,DATA!$BJ:$BJ,"Hot Humid")+COUNTIFS(DATA!$BP:$BP,$A4,DATA!$BS:$BS,"Hot Humid")+COUNTIFS(DATA!$BY:$BY,$A4,DATA!$CB:$CB,"Hot Humid")+COUNTIFS(DATA!$CH:$CH,$A4,DATA!$CK:$CK,"Hot Humid") | E4: =COUNTIFS(DATA!$AO:$AO,$A4,DATA!$AR:$AR,"Post-Monsoon")+COUNTIFS(DATA!$AX:$AX,$A4,DATA!$BA:$BA,"Post-Monsoon")+COUNTIFS(DATA!$BG:$BG,$A4,DATA!$BJ:$BJ,"Post-Monsoon")+COUNTIFS(DATA!$BP:$BP,$A4,DATA!$BS:$BS,"Post-Monsoon")+COUNTIFS(DATA!$BY:$BY,$A4,DATA!$CB:$CB,"Post-Monsoon")+COUNTIFS(DATA!$CH:$CH,$A4,DATA!$CK:$CK,"Post-Monsoon") | F4: =SUM(B4:E4) | G4: =IF(F4=0,"—",INDEX({"Cold Winter";"Hot Dry";"Hot Humid";"Post-Monsoon"},MATCH(MAX(B4:E4),B4:E4,0))) | H4: =IFERROR(MAX(B4:E4)/F4,"") | I4: =IFERROR(VLOOKUP($A4,DECODE!$K$3:$L$21,2,FALSE),"") | J4: =IF(OR(I4="Non-Seasonal",I4="Gel"),"—",IF(G4=I4,"Matches","No Match")) | K4: =IF(J4="—",IF(I4="Gel","—","Evergreen"),IF(H4>=0.4,"Highly Seasonal",IF(H4>=0.3,"Moderately Seasonal","Evergreen"))) | L4: =COUNTIFS(DATA!$AO:$AO,$A4) | M4: =COUNTIFS(DATA!$AO:$AO,$A4,DATA!$AH:$AH,1) | N4: =IFERROR(1-M4/L4,"") | O4: =IFERROR(AVERAGEIFS(DATA!$CW:$CW,DATA!$CN:$CN,$A4),"")
A5: Winter Blackseed | B5: =COUNTIFS(DATA!$AO:$AO,$A5,DATA!$AR:$AR,"Cold Winter")+COUNTIFS(DATA!$AX:$AX,$A5,DATA!$BA:$BA,"Cold Winter")+COUNTIFS(DATA!$BG:$BG,$A5,DATA!$BJ:$BJ,"Cold Winter")+COUNTIFS(DATA!$BP:$BP,$A5,DATA!$BS:$BS,"Cold Winter")+COUNTIFS(DATA!$BY:$BY,$A5,DATA!$CB:$CB,"Cold Winter")+COUNTIFS(DATA!$CH:$CH,$A5,DATA!$CK:$CK,"Cold Winter") | C5: =COUNTIFS(DATA!$AO:$AO,$A5,DATA!$AR:$AR,"Hot Dry")+COUNTIFS(DATA!$AX:$AX,$A5,DATA!$BA:$BA,"Hot Dry")+COUNTIFS(DATA!$BG:$BG,$A5,DATA!$BJ:$BJ,"Hot Dry")+COUNTIFS(DATA!$BP:$BP,$A5,DATA!$BS:$BS,"Hot Dry")+COUNTIFS(DATA!$BY:$BY,$A5,DATA!$CB:$CB,"Hot Dry")+COUNTIFS(DATA!$CH:$CH,$A5,DATA!$CK:$CK,"Hot Dry") | D5: =COUNTIFS(DATA!$AO:$AO,$A5,DATA!$AR:$AR,"Hot Humid")+COUNTIFS(DATA!$AX:$AX,$A5,DATA!$BA:$BA,"Hot Humid")+COUNTIFS(DATA!$BG:$BG,$A5,DATA!$BJ:$BJ,"Hot Humid")+COUNTIFS(DATA!$BP:$BP,$A5,DATA!$BS:$BS,"Hot Humid")+COUNTIFS(DATA!$BY:$BY,$A5,DATA!$CB:$CB,"Hot Humid")+COUNTIFS(DATA!$CH:$CH,$A5,DATA!$CK:$CK,"Hot Humid") | E5: =COUNTIFS(DATA!$AO:$AO,$A5,DATA!$AR:$AR,"Post-Monsoon")+COUNTIFS(DATA!$AX:$AX,$A5,DATA!$BA:$BA,"Post-Monsoon")+COUNTIFS(DATA!$BG:$BG,$A5,DATA!$BJ:$BJ,"Post-Monsoon")+COUNTIFS(DATA!$BP:$BP,$A5,DATA!$BS:$BS,"Post-Monsoon")+COUNTIFS(DATA!$BY:$BY,$A5,DATA!$CB:$CB,"Post-Monsoon")+COUNTIFS(DATA!$CH:$CH,$A5,DATA!$CK:$CK,"Post-Monsoon") | F5: =SUM(B5:E5) | G5: =IF(F5=0,"—",INDEX({"Cold Winter";"Hot Dry";"Hot Humid";"Post-Monsoon"},MATCH(MAX(B5:E5),B5:E5,0))) | H5: =IFERROR(MAX(B5:E5)/F5,"") | I5: =IFERROR(VLOOKUP($A5,DECODE!$K$3:$L$21,2,FALSE),"") | J5: =IF(OR(I5="Non-Seasonal",I5="Gel"),"—",IF(G5=I5,"Matches","No Match")) | K5: =IF(J5="—",IF(I5="Gel","—","Evergreen"),IF(H5>=0.4,"Highly Seasonal",IF(H5>=0.3,"Moderately Seasonal","Evergreen"))) | L5: =COUNTIFS(DATA!$AO:$AO,$A5) | M5: =COUNTIFS(DATA!$AO:$AO,$A5,DATA!$AH:$AH,1) | N5: =IFERROR(1-M5/L5,"") | O5: =IFERROR(AVERAGEIFS(DATA!$CW:$CW,DATA!$CN:$CN,$A5),"")
A6: Flax Bakuchi | B6: =COUNTIFS(DATA!$AO:$AO,$A6,DATA!$AR:$AR,"Cold Winter")+COUNTIFS(DATA!$AX:$AX,$A6,DATA!$BA:$BA,"Cold Winter")+COUNTIFS(DATA!$BG:$BG,$A6,DATA!$BJ:$BJ,"Cold Winter")+COUNTIFS(DATA!$BP:$BP,$A6,DATA!$BS:$BS,"Cold Winter")+COUNTIFS(DATA!$BY:$BY,$A6,DATA!$CB:$CB,"Cold Winter")+COUNTIFS(DATA!$CH:$CH,$A6,DATA!$CK:$CK,"Cold Winter") | C6: =COUNTIFS(DATA!$AO:$AO,$A6,DATA!$AR:$AR,"Hot Dry")+COUNTIFS(DATA!$AX:$AX,$A6,DATA!$BA:$BA,"Hot Dry")+COUNTIFS(DATA!$BG:$BG,$A6,DATA!$BJ:$BJ,"Hot Dry")+COUNTIFS(DATA!$BP:$BP,$A6,DATA!$BS:$BS,"Hot Dry")+COUNTIFS(DATA!$BY:$BY,$A6,DATA!$CB:$CB,"Hot Dry")+COUNTIFS(DATA!$CH:$CH,$A6,DATA!$CK:$CK,"Hot Dry") | D6: =COUNTIFS(DATA!$AO:$AO,$A6,DATA!$AR:$AR,"Hot Humid")+COUNTIFS(DATA!$AX:$AX,$A6,DATA!$BA:$BA,"Hot Humid")+COUNTIFS(DATA!$BG:$BG,$A6,DATA!$BJ:$BJ,"Hot Humid")+COUNTIFS(DATA!$BP:$BP,$A6,DATA!$BS:$BS,"Hot Humid")+COUNTIFS(DATA!$BY:$BY,$A6,DATA!$CB:$CB,"Hot Humid")+COUNTIFS(DATA!$CH:$CH,$A6,DATA!$CK:$CK,"Hot Humid") | E6: =COUNTIFS(DATA!$AO:$AO,$A6,DATA!$AR:$AR,"Post-Monsoon")+COUNTIFS(DATA!$AX:$AX,$A6,DATA!$BA:$BA,"Post-Monsoon")+COUNTIFS(DATA!$BG:$BG,$A6,DATA!$BJ:$BJ,"Post-Monsoon")+COUNTIFS(DATA!$BP:$BP,$A6,DATA!$BS:$BS,"Post-Monsoon")+COUNTIFS(DATA!$BY:$BY,$A6,DATA!$CB:$CB,"Post-Monsoon")+COUNTIFS(DATA!$CH:$CH,$A6,DATA!$CK:$CK,"Post-Monsoon") | F6: =SUM(B6:E6) | G6: =IF(F6=0,"—",INDEX({"Cold Winter";"Hot Dry";"Hot Humid";"Post-Monsoon"},MATCH(MAX(B6:E6),B6:E6,0))) | H6: =IFERROR(MAX(B6:E6)/F6,"") | I6: =IFERROR(VLOOKUP($A6,DECODE!$K$3:$L$21,2,FALSE),"") | J6: =IF(OR(I6="Non-Seasonal",I6="Gel"),"—",IF(G6=I6,"Matches","No Match")) | K6: =IF(J6="—",IF(I6="Gel","—","Evergreen"),IF(H6>=0.4,"Highly Seasonal",IF(H6>=0.3,"Moderately Seasonal","Evergreen"))) | L6: =COUNTIFS(DATA!$AO:$AO,$A6) | M6: =COUNTIFS(DATA!$AO:$AO,$A6,DATA!$AH:$AH,1) | N6: =IFERROR(1-M6/L6,"") | O6: =IFERROR(AVERAGEIFS(DATA!$CW:$CW,DATA!$CN:$CN,$A6),"")
A7: Tomato Rosehip | B7: =COUNTIFS(DATA!$AO:$AO,$A7,DATA!$AR:$AR,"Cold Winter")+COUNTIFS(DATA!$AX:$AX,$A7,DATA!$BA:$BA,"Cold Winter")+COUNTIFS(DATA!$BG:$BG,$A7,DATA!$BJ:$BJ,"Cold Winter")+COUNTIFS(DATA!$BP:$BP,$A7,DATA!$BS:$BS,"Cold Winter")+COUNTIFS(DATA!$BY:$BY,$A7,DATA!$CB:$CB,"Cold Winter")+COUNTIFS(DATA!$CH:$CH,$A7,DATA!$CK:$CK,"Cold Winter") | C7: =COUNTIFS(DATA!$AO:$AO,$A7,DATA!$AR:$AR,"Hot Dry")+COUNTIFS(DATA!$AX:$AX,$A7,DATA!$BA:$BA,"Hot Dry")+COUNTIFS(DATA!$BG:$BG,$A7,DATA!$BJ:$BJ,"Hot Dry")+COUNTIFS(DATA!$BP:$BP,$A7,DATA!$BS:$BS,"Hot Dry")+COUNTIFS(DATA!$BY:$BY,$A7,DATA!$CB:$CB,"Hot Dry")+COUNTIFS(DATA!$CH:$CH,$A7,DATA!$CK:$CK,"Hot Dry") | D7: =COUNTIFS(DATA!$AO:$AO,$A7,DATA!$AR:$AR,"Hot Humid")+COUNTIFS(DATA!$AX:$AX,$A7,DATA!$BA:$BA,"Hot Humid")+COUNTIFS(DATA!$BG:$BG,$A7,DATA!$BJ:$BJ,"Hot Humid")+COUNTIFS(DATA!$BP:$BP,$A7,DATA!$BS:$BS,"Hot Humid")+COUNTIFS(DATA!$BY:$BY,$A7,DATA!$CB:$CB,"Hot Humid")+COUNTIFS(DATA!$CH:$CH,$A7,DATA!$CK:$CK,"Hot Humid") | E7: =COUNTIFS(DATA!$AO:$AO,$A7,DATA!$AR:$AR,"Post-Monsoon")+COUNTIFS(DATA!$AX:$AX,$A7,DATA!$BA:$BA,"Post-Monsoon")+COUNTIFS(DATA!$BG:$BG,$A7,DATA!$BJ:$BJ,"Post-Monsoon")+COUNTIFS(DATA!$BP:$BP,$A7,DATA!$BS:$BS,"Post-Monsoon")+COUNTIFS(DATA!$BY:$BY,$A7,DATA!$CB:$CB,"Post-Monsoon")+COUNTIFS(DATA!$CH:$CH,$A7,DATA!$CK:$CK,"Post-Monsoon") | F7: =SUM(B7:E7) | G7: =IF(F7=0,"—",INDEX({"Cold Winter";"Hot Dry";"Hot Humid";"Post-Monsoon"},MATCH(MAX(B7:E7),B7:E7,0))) | H7: =IFERROR(MAX(B7:E7)/F7,"") | I7: =IFERROR(VLOOKUP($A7,DECODE!$K$3:$L$21,2,FALSE),"") | J7: =IF(OR(I7="Non-Seasonal",I7="Gel"),"—",IF(G7=I7,"Matches","No Match")) | K7: =IF(J7="—",IF(I7="Gel","—","Evergreen"),IF(H7>=0.4,"Highly Seasonal",IF(H7>=0.3,"Moderately Seasonal","Evergreen"))) | L7: =COUNTIFS(DATA!$AO:$AO,$A7) | M7: =COUNTIFS(DATA!$AO:$AO,$A7,DATA!$AH:$AH,1) | N7: =IFERROR(1-M7/L7,"") | O7: =IFERROR(AVERAGEIFS(DATA!$CW:$CW,DATA!$CN:$CN,$A7),"")
A8: Pomegranate Tulsi | B8: =COUNTIFS(DATA!$AO:$AO,$A8,DATA!$AR:$AR,"Cold Winter")+COUNTIFS(DATA!$AX:$AX,$A8,DATA!$BA:$BA,"Cold Winter")+COUNTIFS(DATA!$BG:$BG,$A8,DATA!$BJ:$BJ,"Cold Winter")+COUNTIFS(DATA!$BP:$BP,$A8,DATA!$BS:$BS,"Cold Winter")+COUNTIFS(DATA!$BY:$BY,$A8,DATA!$CB:$CB,"Cold Winter")+COUNTIFS(DATA!$CH:$CH,$A8,DATA!$CK:$CK,"Cold Winter") | C8: =COUNTIFS(DATA!$AO:$AO,$A8,DATA!$AR:$AR,"Hot Dry")+COUNTIFS(DATA!$AX:$AX,$A8,DATA!$BA:$BA,"Hot Dry")+COUNTIFS(DATA!$BG:$BG,$A8,DATA!$BJ:$BJ,"Hot Dry")+COUNTIFS(DATA!$BP:$BP,$A8,DATA!$BS:$BS,"Hot Dry")+COUNTIFS(DATA!$BY:$BY,$A8,DATA!$CB:$CB,"Hot Dry")+COUNTIFS(DATA!$CH:$CH,$A8,DATA!$CK:$CK,"Hot Dry") | D8: =COUNTIFS(DATA!$AO:$AO,$A8,DATA!$AR:$AR,"Hot Humid")+COUNTIFS(DATA!$AX:$AX,$A8,DATA!$BA:$BA,"Hot Humid")+COUNTIFS(DATA!$BG:$BG,$A8,DATA!$BJ:$BJ,"Hot Humid")+COUNTIFS(DATA!$BP:$BP,$A8,DATA!$BS:$BS,"Hot Humid")+COUNTIFS(DATA!$BY:$BY,$A8,DATA!$CB:$CB,"Hot Humid")+COUNTIFS(DATA!$CH:$CH,$A8,DATA!$CK:$CK,"Hot Humid") | E8: =COUNTIFS(DATA!$AO:$AO,$A8,DATA!$AR:$AR,"Post-Monsoon")+COUNTIFS(DATA!$AX:$AX,$A8,DATA!$BA:$BA,"Post-Monsoon")+COUNTIFS(DATA!$BG:$BG,$A8,DATA!$BJ:$BJ,"Post-Monsoon")+COUNTIFS(DATA!$BP:$BP,$A8,DATA!$BS:$BS,"Post-Monsoon")+COUNTIFS(DATA!$BY:$BY,$A8,DATA!$CB:$CB,"Post-Monsoon")+COUNTIFS(DATA!$CH:$CH,$A8,DATA!$CK:$CK,"Post-Monsoon") | F8: =SUM(B8:E8) | G8: =IF(F8=0,"—",INDEX({"Cold Winter";"Hot Dry";"Hot Humid";"Post-Monsoon"},MATCH(MAX(B8:E8),B8:E8,0))) | H8: =IFERROR(MAX(B8:E8)/F8,"") | I8: =IFERROR(VLOOKUP($A8,DECODE!$K$3:$L$21,2,FALSE),"") | J8: =IF(OR(I8="Non-Seasonal",I8="Gel"),"—",IF(G8=I8,"Matches","No Match")) | K8: =IF(J8="—",IF(I8="Gel","—","Evergreen"),IF(H8>=0.4,"Highly Seasonal",IF(H8>=0.3,"Moderately Seasonal","Evergreen"))) | L8: =COUNTIFS(DATA!$AO:$AO,$A8) | M8: =COUNTIFS(DATA!$AO:$AO,$A8,DATA!$AH:$AH,1) | N8: =IFERROR(1-M8/L8,"") | O8: =IFERROR(AVERAGEIFS(DATA!$CW:$CW,DATA!$CN:$CN,$A8),"")
A9: Flax Carrot | B9: =COUNTIFS(DATA!$AO:$AO,$A9,DATA!$AR:$AR,"Cold Winter")+COUNTIFS(DATA!$AX:$AX,$A9,DATA!$BA:$BA,"Cold Winter")+COUNTIFS(DATA!$BG:$BG,$A9,DATA!$BJ:$BJ,"Cold Winter")+COUNTIFS(DATA!$BP:$BP,$A9,DATA!$BS:$BS,"Cold Winter")+COUNTIFS(DATA!$BY:$BY,$A9,DATA!$CB:$CB,"Cold Winter")+COUNTIFS(DATA!$CH:$CH,$A9,DATA!$CK:$CK,"Cold Winter") | C9: =COUNTIFS(DATA!$AO:$AO,$A9,DATA!$AR:$AR,"Hot Dry")+COUNTIFS(DATA!$AX:$AX,$A9,DATA!$BA:$BA,"Hot Dry")+COUNTIFS(DATA!$BG:$BG,$A9,DATA!$BJ:$BJ,"Hot Dry")+COUNTIFS(DATA!$BP:$BP,$A9,DATA!$BS:$BS,"Hot Dry")+COUNTIFS(DATA!$BY:$BY,$A9,DATA!$CB:$CB,"Hot Dry")+COUNTIFS(DATA!$CH:$CH,$A9,DATA!$CK:$CK,"Hot Dry") | D9: =COUNTIFS(DATA!$AO:$AO,$A9,DATA!$AR:$AR,"Hot Humid")+COUNTIFS(DATA!$AX:$AX,$A9,DATA!$BA:$BA,"Hot Humid")+COUNTIFS(DATA!$BG:$BG,$A9,DATA!$BJ:$BJ,"Hot Humid")+COUNTIFS(DATA!$BP:$BP,$A9,DATA!$BS:$BS,"Hot Humid")+COUNTIFS(DATA!$BY:$BY,$A9,DATA!$CB:$CB,"Hot Humid")+COUNTIFS(DATA!$CH:$CH,$A9,DATA!$CK:$CK,"Hot Humid") | E9: =COUNTIFS(DATA!$AO:$AO,$A9,DATA!$AR:$AR,"Post-Monsoon")+COUNTIFS(DATA!$AX:$AX,$A9,DATA!$BA:$BA,"Post-Monsoon")+COUNTIFS(DATA!$BG:$BG,$A9,DATA!$BJ:$BJ,"Post-Monsoon")+COUNTIFS(DATA!$BP:$BP,$A9,DATA!$BS:$BS,"Post-Monsoon")+COUNTIFS(DATA!$BY:$BY,$A9,DATA!$CB:$CB,"Post-Monsoon")+COUNTIFS(DATA!$CH:$CH,$A9,DATA!$CK:$CK,"Post-Monsoon") | F9: =SUM(B9:E9) | G9: =IF(F9=0,"—",INDEX({"Cold Winter";"Hot Dry";"Hot Humid";"Post-Monsoon"},MATCH(MAX(B9:E9),B9:E9,0))) | H9: =IFERROR(MAX(B9:E9)/F9,"") | I9: =IFERROR(VLOOKUP($A9,DECODE!$K$3:$L$21,2,FALSE),"") | J9: =IF(OR(I9="Non-Seasonal",I9="Gel"),"—",IF(G9=I9,"Matches","No Match")) | K9: =IF(J9="—",IF(I9="Gel","—","Evergreen"),IF(H9>=0.4,"Highly Seasonal",IF(H9>=0.3,"Moderately Seasonal","Evergreen"))) | L9: =COUNTIFS(DATA!$AO:$AO,$A9) | M9: =COUNTIFS(DATA!$AO:$AO,$A9,DATA!$AH:$AH,1) | N9: =IFERROR(1-M9/L9,"") | O9: =IFERROR(AVERAGEIFS(DATA!$CW:$CW,DATA!$CN:$CN,$A9),"")
A10: Tomato Vetiver | B10: =COUNTIFS(DATA!$AO:$AO,$A10,DATA!$AR:$AR,"Cold Winter")+COUNTIFS(DATA!$AX:$AX,$A10,DATA!$BA:$BA,"Cold Winter")+COUNTIFS(DATA!$BG:$BG,$A10,DATA!$BJ:$BJ,"Cold Winter")+COUNTIFS(DATA!$BP:$BP,$A10,DATA!$BS:$BS,"Cold Winter")+COUNTIFS(DATA!$BY:$BY,$A10,DATA!$CB:$CB,"Cold Winter")+COUNTIFS(DATA!$CH:$CH,$A10,DATA!$CK:$CK,"Cold Winter") | C10: =COUNTIFS(DATA!$AO:$AO,$A10,DATA!$AR:$AR,"Hot Dry")+COUNTIFS(DATA!$AX:$AX,$A10,DATA!$BA:$BA,"Hot Dry")+COUNTIFS(DATA!$BG:$BG,$A10,DATA!$BJ:$BJ,"Hot Dry")+COUNTIFS(DATA!$BP:$BP,$A10,DATA!$BS:$BS,"Hot Dry")+COUNTIFS(DATA!$BY:$BY,$A10,DATA!$CB:$CB,"Hot Dry")+COUNTIFS(DATA!$CH:$CH,$A10,DATA!$CK:$CK,"Hot Dry") | D10: =COUNTIFS(DATA!$AO:$AO,$A10,DATA!$AR:$AR,"Hot Humid")+COUNTIFS(DATA!$AX:$AX,$A10,DATA!$BA:$BA,"Hot Humid")+COUNTIFS(DATA!$BG:$BG,$A10,DATA!$BJ:$BJ,"Hot Humid")+COUNTIFS(DATA!$BP:$BP,$A10,DATA!$BS:$BS,"Hot Humid")+COUNTIFS(DATA!$BY:$BY,$A10,DATA!$CB:$CB,"Hot Humid")+COUNTIFS(DATA!$CH:$CH,$A10,DATA!$CK:$CK,"Hot Humid") | E10: =COUNTIFS(DATA!$AO:$AO,$A10,DATA!$AR:$AR,"Post-Monsoon")+COUNTIFS(DATA!$AX:$AX,$A10,DATA!$BA:$BA,"Post-Monsoon")+COUNTIFS(DATA!$BG:$BG,$A10,DATA!$BJ:$BJ,"Post-Monsoon")+COUNTIFS(DATA!$BP:$BP,$A10,DATA!$BS:$BS,"Post-Monsoon")+COUNTIFS(DATA!$BY:$BY,$A10,DATA!$CB:$CB,"Post-Monsoon")+COUNTIFS(DATA!$CH:$CH,$A10,DATA!$CK:$CK,"Post-Monsoon") | F10: =SUM(B10:E10) | G10: =IF(F10=0,"—",INDEX({"Cold Winter";"Hot Dry";"Hot Humid";"Post-Monsoon"},MATCH(MAX(B10:E10),B10:E10,0))) | H10: =IFERROR(MAX(B10:E10)/F10,"") | I10: =IFERROR(VLOOKUP($A10,DECODE!$K$3:$L$21,2,FALSE),"") | J10: =IF(OR(I10="Non-Seasonal",I10="Gel"),"—",IF(G10=I10,"Matches","No Match")) | K10: =IF(J10="—",IF(I10="Gel","—","Evergreen"),IF(H10>=0.4,"Highly Seasonal",IF(H10>=0.3,"Moderately Seasonal","Evergreen"))) | L10: =COUNTIFS(DATA!$AO:$AO,$A10) | M10: =COUNTIFS(DATA!$AO:$AO,$A10,DATA!$AH:$AH,1) | N10: =IFERROR(1-M10/L10,"") | O10: =IFERROR(AVERAGEIFS(DATA!$CW:$CW,DATA!$CN:$CN,$A10),"")
A11: GreenApple Tulsi | B11: =COUNTIFS(DATA!$AO:$AO,$A11,DATA!$AR:$AR,"Cold Winter")+COUNTIFS(DATA!$AX:$AX,$A11,DATA!$BA:$BA,"Cold Winter")+COUNTIFS(DATA!$BG:$BG,$A11,DATA!$BJ:$BJ,"Cold Winter")+COUNTIFS(DATA!$BP:$BP,$A11,DATA!$BS:$BS,"Cold Winter")+COUNTIFS(DATA!$BY:$BY,$A11,DATA!$CB:$CB,"Cold Winter")+COUNTIFS(DATA!$CH:$CH,$A11,DATA!$CK:$CK,"Cold Winter") | C11: =COUNTIFS(DATA!$AO:$AO,$A11,DATA!$AR:$AR,"Hot Dry")+COUNTIFS(DATA!$AX:$AX,$A11,DATA!$BA:$BA,"Hot Dry")+COUNTIFS(DATA!$BG:$BG,$A11,DATA!$BJ:$BJ,"Hot Dry")+COUNTIFS(DATA!$BP:$BP,$A11,DATA!$BS:$BS,"Hot Dry")+COUNTIFS(DATA!$BY:$BY,$A11,DATA!$CB:$CB,"Hot Dry")+COUNTIFS(DATA!$CH:$CH,$A11,DATA!$CK:$CK,"Hot Dry") | D11: =COUNTIFS(DATA!$AO:$AO,$A11,DATA!$AR:$AR,"Hot Humid")+COUNTIFS(DATA!$AX:$AX,$A11,DATA!$BA:$BA,"Hot Humid")+COUNTIFS(DATA!$BG:$BG,$A11,DATA!$BJ:$BJ,"Hot Humid")+COUNTIFS(DATA!$BP:$BP,$A11,DATA!$BS:$BS,"Hot Humid")+COUNTIFS(DATA!$BY:$BY,$A11,DATA!$CB:$CB,"Hot Humid")+COUNTIFS(DATA!$CH:$CH,$A11,DATA!$CK:$CK,"Hot Humid") | E11: =COUNTIFS(DATA!$AO:$AO,$A11,DATA!$AR:$AR,"Post-Monsoon")+COUNTIFS(DATA!$AX:$AX,$A11,DATA!$BA:$BA,"Post-Monsoon")+COUNTIFS(DATA!$BG:$BG,$A11,DATA!$BJ:$BJ,"Post-Monsoon")+COUNTIFS(DATA!$BP:$BP,$A11,DATA!$BS:$BS,"Post-Monsoon")+COUNTIFS(DATA!$BY:$BY,$A11,DATA!$CB:$CB,"Post-Monsoon")+COUNTIFS(DATA!$CH:$CH,$A11,DATA!$CK:$CK,"Post-Monsoon") | F11: =SUM(B11:E11) | G11: =IF(F11=0,"—",INDEX({"Cold Winter";"Hot Dry";"Hot Humid";"Post-Monsoon"},MATCH(MAX(B11:E11),B11:E11,0))) | H11: =IFERROR(MAX(B11:E11)/F11,"") | I11: =IFERROR(VLOOKUP($A11,DECODE!$K$3:$L$21,2,FALSE),"") | J11: =IF(OR(I11="Non-Seasonal",I11="Gel"),"—",IF(G11=I11,"Matches","No Match")) | K11: =IF(J11="—",IF(I11="Gel","—","Evergreen"),IF(H11>=0.4,"Highly Seasonal",IF(H11>=0.3,"Moderately Seasonal","Evergreen"))) | L11: =COUNTIFS(DATA!$AO:$AO,$A11) | M11: =COUNTIFS(DATA!$AO:$AO,$A11,DATA!$AH:$AH,1) | N11: =IFERROR(1-M11/L11,"") | O11: =IFERROR(AVERAGEIFS(DATA!$CW:$CW,DATA!$CN:$CN,$A11),"")
A12: Turmeric Nutmeg | B12: =COUNTIFS(DATA!$AO:$AO,$A12,DATA!$AR:$AR,"Cold Winter")+COUNTIFS(DATA!$AX:$AX,$A12,DATA!$BA:$BA,"Cold Winter")+COUNTIFS(DATA!$BG:$BG,$A12,DATA!$BJ:$BJ,"Cold Winter")+COUNTIFS(DATA!$BP:$BP,$A12,DATA!$BS:$BS,"Cold Winter")+COUNTIFS(DATA!$BY:$BY,$A12,DATA!$CB:$CB,"Cold Winter")+COUNTIFS(DATA!$CH:$CH,$A12,DATA!$CK:$CK,"Cold Winter") | C12: =COUNTIFS(DATA!$AO:$AO,$A12,DATA!$AR:$AR,"Hot Dry")+COUNTIFS(DATA!$AX:$AX,$A12,DATA!$BA:$BA,"Hot Dry")+COUNTIFS(DATA!$BG:$BG,$A12,DATA!$BJ:$BJ,"Hot Dry")+COUNTIFS(DATA!$BP:$BP,$A12,DATA!$BS:$BS,"Hot Dry")+COUNTIFS(DATA!$BY:$BY,$A12,DATA!$CB:$CB,"Hot Dry")+COUNTIFS(DATA!$CH:$CH,$A12,DATA!$CK:$CK,"Hot Dry") | D12: =COUNTIFS(DATA!$AO:$AO,$A12,DATA!$AR:$AR,"Hot Humid")+COUNTIFS(DATA!$AX:$AX,$A12,DATA!$BA:$BA,"Hot Humid")+COUNTIFS(DATA!$BG:$BG,$A12,DATA!$BJ:$BJ,"Hot Humid")+COUNTIFS(DATA!$BP:$BP,$A12,DATA!$BS:$BS,"Hot Humid")+COUNTIFS(DATA!$BY:$BY,$A12,DATA!$CB:$CB,"Hot Humid")+COUNTIFS(DATA!$CH:$CH,$A12,DATA!$CK:$CK,"Hot Humid") | E12: =COUNTIFS(DATA!$AO:$AO,$A12,DATA!$AR:$AR,"Post-Monsoon")+COUNTIFS(DATA!$AX:$AX,$A12,DATA!$BA:$BA,"Post-Monsoon")+COUNTIFS(DATA!$BG:$BG,$A12,DATA!$BJ:$BJ,"Post-Monsoon")+COUNTIFS(DATA!$BP:$BP,$A12,DATA!$BS:$BS,"Post-Monsoon")+COUNTIFS(DATA!$BY:$BY,$A12,DATA!$CB:$CB,"Post-Monsoon")+COUNTIFS(DATA!$CH:$CH,$A12,DATA!$CK:$CK,"Post-Monsoon") | F12: =SUM(B12:E12) | G12: =IF(F12=0,"—",INDEX({"Cold Winter";"Hot Dry";"Hot Humid";"Post-Monsoon"},MATCH(MAX(B12:E12),B12:E12,0))) | H12: =IFERROR(MAX(B12:E12)/F12,"") | I12: =IFERROR(VLOOKUP($A12,DECODE!$K$3:$L$21,2,FALSE),"") | J12: =IF(OR(I12="Non-Seasonal",I12="Gel"),"—",IF(G12=I12,"Matches","No Match")) | K12: =IF(J12="—",IF(I12="Gel","—","Evergreen"),IF(H12>=0.4,"Highly Seasonal",IF(H12>=0.3,"Moderately Seasonal","Evergreen"))) | L12: =COUNTIFS(DATA!$AO:$AO,$A12) | M12: =COUNTIFS(DATA!$AO:$AO,$A12,DATA!$AH:$AH,1) | N12: =IFERROR(1-M12/L12,"") | O12: =IFERROR(AVERAGEIFS(DATA!$CW:$CW,DATA!$CN:$CN,$A12),"")
A13: Cocoa Mogra | B13: =COUNTIFS(DATA!$AO:$AO,$A13,DATA!$AR:$AR,"Cold Winter")+COUNTIFS(DATA!$AX:$AX,$A13,DATA!$BA:$BA,"Cold Winter")+COUNTIFS(DATA!$BG:$BG,$A13,DATA!$BJ:$BJ,"Cold Winter")+COUNTIFS(DATA!$BP:$BP,$A13,DATA!$BS:$BS,"Cold Winter")+COUNTIFS(DATA!$BY:$BY,$A13,DATA!$CB:$CB,"Cold Winter")+COUNTIFS(DATA!$CH:$CH,$A13,DATA!$CK:$CK,"Cold Winter") | C13: =COUNTIFS(DATA!$AO:$AO,$A13,DATA!$AR:$AR,"Hot Dry")+COUNTIFS(DATA!$AX:$AX,$A13,DATA!$BA:$BA,"Hot Dry")+COUNTIFS(DATA!$BG:$BG,$A13,DATA!$BJ:$BJ,"Hot Dry")+COUNTIFS(DATA!$BP:$BP,$A13,DATA!$BS:$BS,"Hot Dry")+COUNTIFS(DATA!$BY:$BY,$A13,DATA!$CB:$CB,"Hot Dry")+COUNTIFS(DATA!$CH:$CH,$A13,DATA!$CK:$CK,"Hot Dry") | D13: =COUNTIFS(DATA!$AO:$AO,$A13,DATA!$AR:$AR,"Hot Humid")+COUNTIFS(DATA!$AX:$AX,$A13,DATA!$BA:$BA,"Hot Humid")+COUNTIFS(DATA!$BG:$BG,$A13,DATA!$BJ:$BJ,"Hot Humid")+COUNTIFS(DATA!$BP:$BP,$A13,DATA!$BS:$BS,"Hot Humid")+COUNTIFS(DATA!$BY:$BY,$A13,DATA!$CB:$CB,"Hot Humid")+COUNTIFS(DATA!$CH:$CH,$A13,DATA!$CK:$CK,"Hot Humid") | E13: =COUNTIFS(DATA!$AO:$AO,$A13,DATA!$AR:$AR,"Post-Monsoon")+COUNTIFS(DATA!$AX:$AX,$A13,DATA!$BA:$BA,"Post-Monsoon")+COUNTIFS(DATA!$BG:$BG,$A13,DATA!$BJ:$BJ,"Post-Monsoon")+COUNTIFS(DATA!$BP:$BP,$A13,DATA!$BS:$BS,"Post-Monsoon")+COUNTIFS(DATA!$BY:$BY,$A13,DATA!$CB:$CB,"Post-Monsoon")+COUNTIFS(DATA!$CH:$CH,$A13,DATA!$CK:$CK,"Post-Monsoon") | F13: =SUM(B13:E13) | G13: =IF(F13=0,"—",INDEX({"Cold Winter";"Hot Dry";"Hot Humid";"Post-Monsoon"},MATCH(MAX(B13:E13),B13:E13,0))) | H13: =IFERROR(MAX(B13:E13)/F13,"") | I13: =IFERROR(VLOOKUP($A13,DECODE!$K$3:$L$21,2,FALSE),"") | J13: =IF(OR(I13="Non-Seasonal",I13="Gel"),"—",IF(G13=I13,"Matches","No Match")) | K13: =IF(J13="—",IF(I13="Gel","—","Evergreen"),IF(H13>=0.4,"Highly Seasonal",IF(H13>=0.3,"Moderately Seasonal","Evergreen"))) | L13: =COUNTIFS(DATA!$AO:$AO,$A13) | M13: =COUNTIFS(DATA!$AO:$AO,$A13,DATA!$AH:$AH,1) | N13: =IFERROR(1-M13/L13,"") | O13: =IFERROR(AVERAGEIFS(DATA!$CW:$CW,DATA!$CN:$CN,$A13),"")
A14: Honey Multi-Nut | B14: =COUNTIFS(DATA!$AO:$AO,$A14,DATA!$AR:$AR,"Cold Winter")+COUNTIFS(DATA!$AX:$AX,$A14,DATA!$BA:$BA,"Cold Winter")+COUNTIFS(DATA!$BG:$BG,$A14,DATA!$BJ:$BJ,"Cold Winter")+COUNTIFS(DATA!$BP:$BP,$A14,DATA!$BS:$BS,"Cold Winter")+COUNTIFS(DATA!$BY:$BY,$A14,DATA!$CB:$CB,"Cold Winter")+COUNTIFS(DATA!$CH:$CH,$A14,DATA!$CK:$CK,"Cold Winter") | C14: =COUNTIFS(DATA!$AO:$AO,$A14,DATA!$AR:$AR,"Hot Dry")+COUNTIFS(DATA!$AX:$AX,$A14,DATA!$BA:$BA,"Hot Dry")+COUNTIFS(DATA!$BG:$BG,$A14,DATA!$BJ:$BJ,"Hot Dry")+COUNTIFS(DATA!$BP:$BP,$A14,DATA!$BS:$BS,"Hot Dry")+COUNTIFS(DATA!$BY:$BY,$A14,DATA!$CB:$CB,"Hot Dry")+COUNTIFS(DATA!$CH:$CH,$A14,DATA!$CK:$CK,"Hot Dry") | D14: =COUNTIFS(DATA!$AO:$AO,$A14,DATA!$AR:$AR,"Hot Humid")+COUNTIFS(DATA!$AX:$AX,$A14,DATA!$BA:$BA,"Hot Humid")+COUNTIFS(DATA!$BG:$BG,$A14,DATA!$BJ:$BJ,"Hot Humid")+COUNTIFS(DATA!$BP:$BP,$A14,DATA!$BS:$BS,"Hot Humid")+COUNTIFS(DATA!$BY:$BY,$A14,DATA!$CB:$CB,"Hot Humid")+COUNTIFS(DATA!$CH:$CH,$A14,DATA!$CK:$CK,"Hot Humid") | E14: =COUNTIFS(DATA!$AO:$AO,$A14,DATA!$AR:$AR,"Post-Monsoon")+COUNTIFS(DATA!$AX:$AX,$A14,DATA!$BA:$BA,"Post-Monsoon")+COUNTIFS(DATA!$BG:$BG,$A14,DATA!$BJ:$BJ,"Post-Monsoon")+COUNTIFS(DATA!$BP:$BP,$A14,DATA!$BS:$BS,"Post-Monsoon")+COUNTIFS(DATA!$BY:$BY,$A14,DATA!$CB:$CB,"Post-Monsoon")+COUNTIFS(DATA!$CH:$CH,$A14,DATA!$CK:$CK,"Post-Monsoon") | F14: =SUM(B14:E14) | G14: =IF(F14=0,"—",INDEX({"Cold Winter";"Hot Dry";"Hot Humid";"Post-Monsoon"},MATCH(MAX(B14:E14),B14:E14,0))) | H14: =IFERROR(MAX(B14:E14)/F14,"") | I14: =IFERROR(VLOOKUP($A14,DECODE!$K$3:$L$21,2,FALSE),"") | J14: =IF(OR(I14="Non-Seasonal",I14="Gel"),"—",IF(G14=I14,"Matches","No Match")) | K14: =IF(J14="—",IF(I14="Gel","—","Evergreen"),IF(H14>=0.4,"Highly Seasonal",IF(H14>=0.3,"Moderately Seasonal","Evergreen"))) | L14: =COUNTIFS(DATA!$AO:$AO,$A14) | M14: =COUNTIFS(DATA!$AO:$AO,$A14,DATA!$AH:$AH,1) | N14: =IFERROR(1-M14/L14,"") | O14: =IFERROR(AVERAGEIFS(DATA!$CW:$CW,DATA!$CN:$CN,$A14),"")
... A21: Aloe Vera | B21: =COUNTIFS(DATA!$AO:$AO,$A21,DATA!$AR:$AR,"Cold Winter")+COUNTIFS(DATA!$AX:$AX,$A21,DATA!$BA:$BA,"Cold Winter")+COUNTIFS(DATA!$BG:$BG,$A21,DATA!$BJ:$BJ,"Cold Winter")+COUNTIFS(DATA!$BP:$BP,$A21,DATA!$BS:$BS,"Cold Winter")+COUNTIFS(DATA!$BY:$BY,$A21,DATA!$CB:$CB,"Cold Winter")+COUNTIFS(DATA!$CH:$CH,$A21,DATA!$CK:$CK,"Cold Winter") | C21: =COUNTIFS(DATA!$AO:$AO,$A21,DATA!$AR:$AR,"Hot Dry")+COUNTIFS(DATA!$AX:$AX,$A21,DATA!$BA:$BA,"Hot Dry")+COUNTIFS(DATA!$BG:$BG,$A21,DATA!$BJ:$BJ,"Hot Dry")+COUNTIFS(DATA!$BP:$BP,$A21,DATA!$BS:$BS,"Hot Dry")+COUNTIFS(DATA!$BY:$BY,$A21,DATA!$CB:$CB,"Hot Dry")+COUNTIFS(DATA!$CH:$CH,$A21,DATA!$CK:$CK,"Hot Dry") | D21: =COUNTIFS(DATA!$AO:$AO,$A21,DATA!$AR:$AR,"Hot Humid")+COUNTIFS(DATA!$AX:$AX,$A21,DATA!$BA:$BA,"Hot Humid")+COUNTIFS(DATA!$BG:$BG,$A21,DATA!$BJ:$BJ,"Hot Humid")+COUNTIFS(DATA!$BP:$BP,$A21,DATA!$BS:$BS,"Hot Humid")+COUNTIFS(DATA!$BY:$BY,$A21,DATA!$CB:$CB,"Hot Humid")+COUNTIFS(DATA!$CH:$CH,$A21,DATA!$CK:$CK,"Hot Humid") | E21: =COUNTIFS(DATA!$AO:$AO,$A21,DATA!$AR:$AR,"Post-Monsoon")+COUNTIFS(DATA!$AX:$AX,$A21,DATA!$BA:$BA,"Post-Monsoon")+COUNTIFS(DATA!$BG:$BG,$A21,DATA!$BJ:$BJ,"Post-Monsoon")+COUNTIFS(DATA!$BP:$BP,$A21,DATA!$BS:$BS,"Post-Monsoon")+COUNTIFS(DATA!$BY:$BY,$A21,DATA!$CB:$CB,"Post-Monsoon")+COUNTIFS(DATA!$CH:$CH,$A21,DATA!$CK:$CK,"Post-Monsoon") | F21: =SUM(B21:E21) | G21: =IF(F21=0,"—",INDEX({"Cold Winter";"Hot Dry";"Hot Humid";"Post-Monsoon"},MATCH(MAX(B21:E21),B21:E21,0))) | H21: =IFERROR(MAX(B21:E21)/F21,"") | I21: =IFERROR(VLOOKUP($A21,DECODE!$K$3:$L$21,2,FALSE),"") | J21: =IF(OR(I21="Non-Seasonal",I21="Gel"),"—",IF(G21=I21,"Matches","No Match")) | K21: =IF(J21="—",IF(I21="Gel","—","Evergreen"),IF(H21>=0.4,"Highly Seasonal",IF(H21>=0.3,"Moderately Seasonal","Evergreen"))) | L21: =COUNTIFS(DATA!$AO:$AO,$A21) | M21: =COUNTIFS(DATA!$AO:$AO,$A21,DATA!$AH:$AH,1) | N21: =IFERROR(1-M21/L21,"") | O21: =IFERROR(AVERAGEIFS(DATA!$CW:$CW,DATA!$CN:$CN,$A21),"")
B22: =SUM(B3:B21) | C22: =SUM(C3:C21) | D22: =SUM(D3:D21) | E22: =SUM(E3:E21) | F22: =SUM(F3:F21)

Sheet GRAMMAGE
A1: GRAMMAGE TRANSITIONS — entry SKU → 2nd order (whole workbook)
A3: Category | B3: Entry Size | C3: Total Next Purchases | D3: Repeat Exact Same | E3: Repeat % | F3: Upsized | G3: Upsize % | H3: Lateral | I3: Downsize | J3: Downsize % | K3: Same Size Diff Variant | L3: FM30→FM50 | M3: FM30→AG50 | N3: FM50→FM30 | O3: AG50→FM30
A4: Face Malai | B4: 30 | C4: =COUNTIFS(DATA!$CM:$CM,"Face Malai",DATA!$CO:$CO,30,DATA!$CQ:$CQ,1) | D4: =COUNTIFS(DATA!$CM:$CM,"Face Malai",DATA!$CO:$CO,30,DATA!$CQ:$CQ,1,DATA!$CV:$CV,"Repeat Exact") | E4: =IFERROR(D4/C4,"") | F4: =COUNTIFS(DATA!$CM:$CM,"Face Malai",DATA!$CO:$CO,30,DATA!$CQ:$CQ,1,DATA!$CV:$CV,"Upsized") | G4: =IFERROR(F4/C4,"") | H4: =COUNTIFS(DATA!$CM:$CM,"Face Malai",DATA!$CO:$CO,30,DATA!$CQ:$CQ,1,DATA!$CV:$CV,"Lateral") | I4: =COUNTIFS(DATA!$CM:$CM,"Face Malai",DATA!$CO:$CO,30,DATA!$CQ:$CQ,1,DATA!$CV:$CV,"Downsized") | J4: =IFERROR(I4/C4,"") | K4: =COUNTIFS(DATA!$CM:$CM,"Face Malai",DATA!$CO:$CO,30,DATA!$CQ:$CQ,1,DATA!$CV:$CV,"Same Size Diff Variant") | L4: =COUNTIFS(DATA!$CM:$CM,"Face Malai",DATA!$CO:$CO,30,DATA!$CR:$CR,"Face Malai",DATA!$CT:$CT,50) | M4: =COUNTIFS(DATA!$CM:$CM,"Face Malai",DATA!$CO:$CO,30,DATA!$CR:$CR,"Active Gel",DATA!$CT:$CT,50)
A5: Face Malai | B5: 50 | C5: =COUNTIFS(DATA!$CM:$CM,"Face Malai",DATA!$CO:$CO,50,DATA!$CQ:$CQ,1) | D5: =COUNTIFS(DATA!$CM:$CM,"Face Malai",DATA!$CO:$CO,50,DATA!$CQ:$CQ,1,DATA!$CV:$CV,"Repeat Exact") | E5: =IFERROR(D5/C5,"") | F5: =COUNTIFS(DATA!$CM:$CM,"Face Malai",DATA!$CO:$CO,50,DATA!$CQ:$CQ,1,DATA!$CV:$CV,"Upsized") | G5: =IFERROR(F5/C5,"") | H5: =COUNTIFS(DATA!$CM:$CM,"Face Malai",DATA!$CO:$CO,50,DATA!$CQ:$CQ,1,DATA!$CV:$CV,"Lateral") | I5: =COUNTIFS(DATA!$CM:$CM,"Face Malai",DATA!$CO:$CO,50,DATA!$CQ:$CQ,1,DATA!$CV:$CV,"Downsized") | J5: =IFERROR(I5/C5,"") | K5: =COUNTIFS(DATA!$CM:$CM,"Face Malai",DATA!$CO:$CO,50,DATA!$CQ:$CQ,1,DATA!$CV:$CV,"Same Size Diff Variant") | N5: =COUNTIFS(DATA!$CM:$CM,"Face Malai",DATA!$CO:$CO,50,DATA!$CR:$CR,"Face Malai",DATA!$CT:$CT,30)
A6: Active Gel | B6: 50 | C6: =COUNTIFS(DATA!$CM:$CM,"Active Gel",DATA!$CO:$CO,50,DATA!$CQ:$CQ,1) | D6: =COUNTIFS(DATA!$CM:$CM,"Active Gel",DATA!$CO:$CO,50,DATA!$CQ:$CQ,1,DATA!$CV:$CV,"Repeat Exact") | E6: =IFERROR(D6/C6,"") | F6: =COUNTIFS(DATA!$CM:$CM,"Active Gel",DATA!$CO:$CO,50,DATA!$CQ:$CQ,1,DATA!$CV:$CV,"Upsized") | G6: =IFERROR(F6/C6,"") | H6: =COUNTIFS(DATA!$CM:$CM,"Active Gel",DATA!$CO:$CO,50,DATA!$CQ:$CQ,1,DATA!$CV:$CV,"Lateral") | I6: =COUNTIFS(DATA!$CM:$CM,"Active Gel",DATA!$CO:$CO,50,DATA!$CQ:$CQ,1,DATA!$CV:$CV,"Downsized") | J6: =IFERROR(I6/C6,"") | K6: =COUNTIFS(DATA!$CM:$CM,"Active Gel",DATA!$CO:$CO,50,DATA!$CQ:$CQ,1,DATA!$CV:$CV,"Same Size Diff Variant") | O6: =COUNTIFS(DATA!$CM:$CM,"Active Gel",DATA!$CO:$CO,50,DATA!$CR:$CR,"Face Malai",DATA!$CT:$CT,30)
A7: Aloe Vera Gel | B7: 40 | C7: =COUNTIFS(DATA!$CM:$CM,"Aloe Vera Gel",DATA!$CO:$CO,40,DATA!$CQ:$CQ,1) | D7: =COUNTIFS(DATA!$CM:$CM,"Aloe Vera Gel",DATA!$CO:$CO,40,DATA!$CQ:$CQ,1,DATA!$CV:$CV,"Repeat Exact") | E7: =IFERROR(D7/C7,"") | F7: =COUNTIFS(DATA!$CM:$CM,"Aloe Vera Gel",DATA!$CO:$CO,40,DATA!$CQ:$CQ,1,DATA!$CV:$CV,"Upsized") | G7: =IFERROR(F7/C7,"") | H7: =COUNTIFS(DATA!$CM:$CM,"Aloe Vera Gel",DATA!$CO:$CO,40,DATA!$CQ:$CQ,1,DATA!$CV:$CV,"Lateral") | I7: =COUNTIFS(DATA!$CM:$CM,"Aloe Vera Gel",DATA!$CO:$CO,40,DATA!$CQ:$CQ,1,DATA!$CV:$CV,"Downsized") | J7: =IFERROR(I7/C7,"") | K7: =COUNTIFS(DATA!$CM:$CM,"Aloe Vera Gel",DATA!$CO:$CO,40,DATA!$CQ:$CQ,1,DATA!$CV:$CV,"Same Size Diff Variant")
A8: Aloe Vera Gel | B8: 80 | C8: =COUNTIFS(DATA!$CM:$CM,"Aloe Vera Gel",DATA!$CO:$CO,80,DATA!$CQ:$CQ,1) | D8: =COUNTIFS(DATA!$CM:$CM,"Aloe Vera Gel",DATA!$CO:$CO,80,DATA!$CQ:$CQ,1,DATA!$CV:$CV,"Repeat Exact") | E8: =IFERROR(D8/C8,"") | F8: =COUNTIFS(DATA!$CM:$CM,"Aloe Vera Gel",DATA!$CO:$CO,80,DATA!$CQ:$CQ,1,DATA!$CV:$CV,"Upsized") | G8: =IFERROR(F8/C8,"") | H8: =COUNTIFS(DATA!$CM:$CM,"Aloe Vera Gel",DATA!$CO:$CO,80,DATA!$CQ:$CQ,1,DATA!$CV:$CV,"Lateral") | I8: =COUNTIFS(DATA!$CM:$CM,"Aloe Vera Gel",DATA!$CO:$CO,80,DATA!$CQ:$CQ,1,DATA!$CV:$CV,"Downsized") | J8: =IFERROR(I8/C8,"") | K8: =COUNTIFS(DATA!$CM:$CM,"Aloe Vera Gel",DATA!$CO:$CO,80,DATA!$CQ:$CQ,1,DATA!$CV:$CV,"Same Size Diff Variant")
A9: TOTAL | C9: =SUM(C4:C8) | D9: =SUM(D4:D8) | E9: =IFERROR(D9/C9,"") | F9: =SUM(F4:F8) | G9: =IFERROR(F9/C9,"") | H9: =SUM(H4:H8) | I9: =SUM(I4:I8) | J9: =IFERROR(I9/C9,"") | K9: =SUM(K4:K8)

Sheet DATA
A1: Name | B1: category_first | C1: category_2nd | D1: category_3rd | E1: category_4th | F1: category_5th | G1: category_6th | H1: first_purchased_short_code | I1: second_purchased_short_code | J1: third_purchased_short_code | K1: fourth_purchased_short_code | L1: fifth_purchased_short_code | M1: sixth_purchased_short_code | N1: first_purchased_sku | O1: second_purchased_sku | P1: third_purchased_sku | Q1: fourth_purchased_sku | R1: fifth_purchased_sku | S1: sixth_purchased_sku | T1: first_order_date | U1: second_order_date | V1: third_order_date | W1: fourth_order_date | X1: fifth_order_date | Y1: sixth_order_date | Z1: days_between_1st_and_2nd | AA1: days_between_2nd_and_3rd | AB1: days_between_3rd_and_4th | AC1: days_between_4th_and_5th | AD1: days_between_5th_and_6th | AE1: city | AF1: Month-Year | AG1: Month Number | AH1: Journey Depth | AI1: Is Repeat Buyer? | AJ1: Region | AK1: first code | AL1: first line | AM1: first vcode | AN1: first category | AO1: first variant | AP1: first size | AQ1: first date | AR1: first season | AS1: first intent | AT1: second code | AU1: second line | AV1: second vcode | AW1: second category | AX1: second variant | AY1: second size | AZ1: second date | BA1: second season | BB1: second intent | BC1: third code | BD1: third line | BE1: third vcode | BF1: third category | BG1: third variant | BH1: third size | BI1: third date | BJ1: third season | BK1: third intent | BL1: fourth code | BM1: fourth line | BN1: fourth vcode | BO1: fourth category | BP1: fourth variant | BQ1: fourth size | BR1: fourth date | BS1: fourth season | BT1: fourth intent | BU1: fifth code | BV1: fifth line | BW1: fifth vcode | BX1: fifth category | BY1: fifth variant | BZ1: fifth size | CA1: fifth date | CB1: fifth season | CC1: fifth intent | CD1: sixth code | CE1: sixth line | CF1: sixth vcode | CG1: sixth category | CH1: sixth variant | CI1: sixth size | CJ1: sixth date | CK1: sixth season | CL1: sixth intent | CM1: entry category | CN1: entry variant | CO1: entry size | CP1: entry sku | CQ1: has next? | CR1: next category | CS1: next variant | CT1: next size | CU1: next sku | CV1: move type | CW1: gap days | CX1: V2V hit | CY1: V2C hit | CZ1: in cohort?
A2: 27692 | B2: Face Malai | H2: Turmeric Nutmeg (Pigmentation) Face Malai - 50g | N2: FC-DM-PG-050 | T2: Jan 15, 2026 | AE2: Gurgaon | AF2: 2026-01 | AG2: 1 | AH2: 1 | AI2: 0 | AJ2: =IF($AE2="","",IFERROR(VLOOKUP(TRIM($AE2),DECODE!$H$3:$I$60,2,FALSE),"Rest of India")) | AK2: =IF($N2="","",UPPER(TRIM(LEFT($N2&",",FIND(",",$N2&",")-1)))) | AL2: =IF($AK2="","",MID($AK2,4,FIND("~",SUBSTITUTE($AK2,"-","~",2))-4)) | AM2: =IF($AK2="","",MID($AK2,FIND("~",SUBSTITUTE($AK2,"-","~",2))+1,FIND("~",SUBSTITUTE($AK2,"-","~",3))-FIND("~",SUBSTITUTE($AK2,"-","~",2))-1)) | AN2: =IF($AL2="","",IFERROR(VLOOKUP($AL2,DECODE!$A$3:$C$8,3,FALSE),"?")) | AO2: =IF($AM2="","",IFERROR(VLOOKUP($AL2&"-"&$AM2,DECODE!$E$3:$F$21,2,FALSE),"?")) | AP2: =IF($AK2="","",IFERROR(VALUE(RIGHT($AK2,3)),"")) | AQ2: =IF($T2="","",IFERROR(IF(ISNUMBER($T2),$T2,DATEVALUE(TRIM($T2))),"")) | AR2: =IF($AQ2="","",IF(MONTH($AQ2)>=12,"Cold Winter",IF(MONTH($AQ2)>=10,"Post-Monsoon",IF(MONTH($AQ2)>=6,"Hot Humid",IF(MONTH($AQ2)>=3,"Hot Dry","Cold Winter"))))) | AS2: =IF($AL2="","",IFERROR(VLOOKUP($AL2,DECODE!$A$3:$C$8,2,FALSE),"?")) | AT2: =IF($O2="","",UPPER(TRIM(LEFT($O2&",",FIND(",",$O2&",")-1)))) | AU2: =IF($AT2="","",MID($AT2,4,FIND("~",SUBSTITUTE($AT2,"-","~",2))-4)) | AV2: =IF($AT2="","",MID($AT2,FIND("~",SUBSTITUTE($AT2,"-","~",2))+1,FIND("~",SUBSTITUTE($AT2,"-","~",3))-FIND("~",SUBSTITUTE($AT2,"-","~",2))-1)) | AW2: =IF($AU2="","",IFERROR(VLOOKUP($AU2,DECODE!$A$3:$C$8,3,FALSE),"?")) | AX2: =IF($AV2="","",IFERROR(VLOOKUP($AU2&"-"&$AV2,DECODE!$E$3:$F$21,2,FALSE),"?")) | AY2: =IF($AT2="","",IFERROR(VALUE(RIGHT($AT2,3)),"")) | AZ2: =IF($U2="","",IFERROR(IF(ISNUMBER($U2),$U2,DATEVALUE(TRIM($U2))),"")) | BA2: =IF($AZ2="","",IF(MONTH($AZ2)>=12,"Cold Winter",IF(MONTH($AZ2)>=10,"Post-Monsoon",IF(MONTH($AZ2)>=6,"Hot Humid",IF(MONTH($AZ2)>=3,"Hot Dry","Cold Winter"))))) | BB2: =IF($AU2="","",IFERROR(VLOOKUP($AU2,DECODE!$A$3:$C$8,2,FALSE),"?")) | BC2: =IF($P2="","",UPPER(TRIM(LEFT($P2&",",FIND(",",$P2&",")-1)))) | BD2: =IF($BC2="","",MID($BC2,4,FIND("~",SUBSTITUTE($BC2,"-","~",2))-4)) | BE2: =IF($BC2="","",MID($BC2,FIND("~",SUBSTITUTE($BC2,"-","~",2))+1,FIND("~",SUBSTITUTE($BC2,"-","~",3))-FIND("~",SUBSTITUTE($BC2,"-","~",2))-1)) | BF2: =IF($BD2="","",IFERROR(VLOOKUP($BD2,DECODE!$A$3:$C$8,3,FALSE),"?")) | BG2: =IF($BE2="","",IFERROR(VLOOKUP($BD2&"-"&$BE2,DECODE!$E$3:$F$21,2,FALSE),"?")) | BH2: =IF($BC2="","",IFERROR(VALUE(RIGHT($BC2,3)),"")) | BI2: =IF($V2="","",IFERROR(IF(ISNUMBER($V2),$V2,DATEVALUE(TRIM($V2))),"")) | BJ2: =IF($BI2="","",IF(MONTH($BI2)>=12,"Cold Winter",IF(MONTH($BI2)>=10,"Post-Monsoon",IF(MONTH($BI2)>=6,"Hot Humid",IF(MONTH($BI2)>=3,"Hot Dry","Cold Winter"))))) | BK2: =IF($BD2="","",IFERROR(VLOOKUP($BD2,DECODE!$A$3:$C$8,2,FALSE),"?")) | BL2: =IF($Q2="","",UPPER(TRIM(LEFT($Q2&",",FIND(",",$Q2&",")-1)))) | BM2: =IF($BL2="","",MID($BL2,4,FIND("~",SUBSTITUTE($BL2,"-","~",2))-4)) | BN2: =IF($BL2="","",MID($BL2,FIND("~",SUBSTITUTE($BL2,"-","~",2))+1,FIND("~",SUBSTITUTE($BL2,"-","~",3))-FIND("~",SUBSTITUTE($BL2,"-","~",2))-1)) | BO2: =IF($BM2="","",IFERROR(VLOOKUP($BM2,DECODE!$A$3:$C$8,3,FALSE),"?")) | BP2: =IF($BN2="","",IFERROR(VLOOKUP($BM2&"-"&$BN2,DECODE!$E$3:$F$21,2,FALSE),"?")) | BQ2: =IF($BL2="","",IFERROR(VALUE(RIGHT($BL2,3)),"")) | BR2: =IF($W2="","",IFERROR(IF(ISNUMBER($W2),$W2,DATEVALUE(TRIM($W2))),"")) | BS2: =IF($BR2="","",IF(MONTH($BR2)>=12,"Cold Winter",IF(MONTH($BR2)>=10,"Post-Monsoon",IF(MONTH($BR2)>=6,"Hot Humid",IF(MONTH($BR2)>=3,"Hot Dry","Cold Winter"))))) | BT2: =IF($BM2="","",IFERROR(VLOOKUP($BM2,DECODE!$A$3:$C$8,2,FALSE),"?")) | BU2: =IF($R2="","",UPPER(TRIM(LEFT($R2&",",FIND(",",$R2&",")-1)))) | BV2: =IF($BU2="","",MID($BU2,4,FIND("~",SUBSTITUTE($BU2,"-","~",2))-4)) | BW2: =IF($BU2="","",MID($BU2,FIND("~",SUBSTITUTE($BU2,"-","~",2))+1,FIND("~",SUBSTITUTE($BU2,"-","~",3))-FIND("~",SUBSTITUTE($BU2,"-","~",2))-1)) | BX2: =IF($BV2="","",IFERROR(VLOOKUP($BV2,DECODE!$A$3:$C$8,3,FALSE),"?")) | BY2: =IF($BW2="","",IFERROR(VLOOKUP($BV2&"-"&$BW2,DECODE!$E$3:$F$21,2,FALSE),"?")) | BZ2: =IF($BU2="","",IFERROR(VALUE(RIGHT($BU2,3)),"")) | CA2: =IF($X2="","",IFERROR(IF(ISNUMBER($X2),$X2,DATEVALUE(TRIM($X2))),"")) | CB2: =IF($CA2="","",IF(MONTH($CA2)>=12,"Cold Winter",IF(MONTH($CA2)>=10,"Post-Monsoon",IF(MONTH($CA2)>=6,"Hot Humid",IF(MONTH($CA2)>=3,"Hot Dry","Cold Winter"))))) | CC2: =IF($BV2="","",IFERROR(VLOOKUP($BV2,DECODE!$A$3:$C$8,2,FALSE),"?")) | CD2: =IF($S2="","",UPPER(TRIM(LEFT($S2&",",FIND(",",$S2&",")-1)))) | CE2: =IF($CD2="","",MID($CD2,4,FIND("~",SUBSTITUTE($CD2,"-","~",2))-4)) | CF2: =IF($CD2="","",MID($CD2,FIND("~",SUBSTITUTE($CD2,"-","~",2))+1,FIND("~",SUBSTITUTE($CD2,"-","~",3))-FIND("~",SUBSTITUTE($CD2,"-","~",2))-1)) | CG2: =IF($CE2="","",IFERROR(VLOOKUP($CE2,DECODE!$A$3:$C$8,3,FALSE),"?")) | CH2: =IF($CF2="","",IFERROR(VLOOKUP($CE2&"-"&$CF2,DECODE!$E$3:$F$21,2,FALSE),"?")) | CI2: =IF($CD2="","",IFERROR(VALUE(RIGHT($CD2,3)),"")) | CJ2: =IF($Y2="","",IFERROR(IF(ISNUMBER($Y2),$Y2,DATEVALUE(TRIM($Y2))),"")) | CK2: =IF($CJ2="","",IF(MONTH($CJ2)>=12,"Cold Winter",IF(MONTH($CJ2)>=10,"Post-Monsoon",IF(MONTH($CJ2)>=6,"Hot Humid",IF(MONTH($CJ2)>=3,"Hot Dry","Cold Winter"))))) | CL2: =IF($CE2="","",IFERROR(VLOOKUP($CE2,DECODE!$A$3:$C$8,2,FALSE),"?")) | CM2: =IF($AN2="","",AN2) | CN2: =IF($AO2="","",AO2) | CO2: =IF($AP2="","",AP2) | CP2: =IF($CM2="","",IF($CM2="Aloe Vera Gel","Aloe Vera Gel "&$CO2&"g",CN2&" "&$CO2&"g")) | CQ2: =IF($AT2="",0,1) | CR2: =IF($CQ2=0,"",AW2) | CS2: =IF($CQ2=0,"",AX2) | CT2: =IF($CQ2=0,"",AY2) | CU2: =IF($CR2="","",IF($CR2="Aloe Vera Gel","Aloe Vera Gel "&$CT2&"g",CS2&" "&$CT2&"g")) | CV2: =IF($CQ2=0,"",IF($CP2=$CU2,"Repeat Exact",IF($CT2>$CO2,"Upsized",IF($CT2<$CO2,"Downsized",IF($CM2<>$CR2,"Lateral","Same Size Diff Variant"))))) | CW2: =IF($CQ2=0,"",AZ2-AQ2) | CX2: =IF($CQ2=0,0,IF(CS2=CN2,1,0)) | CY2: =IF($CQ2=0,0,IF(CR2=CM2,1,0)) | CZ2: =IF($A2="","",IF(AND(IF(DASHBOARD!$C$4="All",TRUE,$CM2=DASHBOARD!$C$4),IF(DASHBOARD!$C$6="All",TRUE,$CP2=DASHBOARD!$C$6),IF(DASHBOARD!$C$8="All",TRUE,$AF2>=DASHBOARD!$C$8),IF(DASHBOARD!$C$10="All",TRUE,$AF2<=DASHBOARD!$C$10),IF(DASHBOARD!$C$12="All",TRUE,$AH2=VALUE(DASHBOARD!$C$12)),IF(DASHBOARD!$C$14="All",TRUE,$AJ2=DASHBOARD!$C$14)),1,0))
A3: 27835 | B3: Face Malai | H3: Flax Carrot (Hot Humid) 35+ Face Malai - 50g | N3: FC-HHDM-FC-050 | T3: Jun 22, 2026 | AE3: Gurgaon | AF3: 2026-06 | AG3: 6 | AH3: 1 | AI3: 0 | AJ3: =IF($AE3="","",IFERROR(VLOOKUP(TRIM($AE3),DECODE!$H$3:$I$60,2,FALSE),"Rest of India")) | AK3: =IF($N3="","",UPPER(TRIM(LEFT($N3&",",FIND(",",$N3&",")-1)))) | AL3: =IF($AK3="","",MID($AK3,4,FIND("~",SUBSTITUTE($AK3,"-","~",2))-4)) | AM3: =IF($AK3="","",MID($AK3,FIND("~",SUBSTITUTE($AK3,"-","~",2))+1,FIND("~",SUBSTITUTE($AK3,"-","~",3))-FIND("~",SUBSTITUTE($AK3,"-","~",2))-1)) | AN3: =IF($AL3="","",IFERROR(VLOOKUP($AL3,DECODE!$A$3:$C$8,3,FALSE),"?")) | AO3: =IF($AM3="","",IFERROR(VLOOKUP($AL3&"-"&$AM3,DECODE!$E$3:$F$21,2,FALSE),"?")) | AP3: =IF($AK3="","",IFERROR(VALUE(RIGHT($AK3,3)),"")) | AQ3: =IF($T3="","",IFERROR(IF(ISNUMBER($T3),$T3,DATEVALUE(TRIM($T3))),"")) | AR3: =IF($AQ3="","",IF(MONTH($AQ3)>=12,"Cold Winter",IF(MONTH($AQ3)>=10,"Post-Monsoon",IF(MONTH($AQ3)>=6,"Hot Humid",IF(MONTH($AQ3)>=3,"Hot Dry","Cold Winter"))))) | AS3: =IF($AL3="","",IFERROR(VLOOKUP($AL3,DECODE!$A$3:$C$8,2,FALSE),"?")) | AT3: =IF($O3="","",UPPER(TRIM(LEFT($O3&",",FIND(",",$O3&",")-1)))) | AU3: =IF($AT3="","",MID($AT3,4,FIND("~",SUBSTITUTE($AT3,"-","~",2))-4)) | AV3: =IF($AT3="","",MID($AT3,FIND("~",SUBSTITUTE($AT3,"-","~",2))+1,FIND("~",SUBSTITUTE($AT3,"-","~",3))-FIND("~",SUBSTITUTE($AT3,"-","~",2))-1)) | AW3: =IF($AU3="","",IFERROR(VLOOKUP($AU3,DECODE!$A$3:$C$8,3,FALSE),"?")) | AX3: =IF($AV3="","",IFERROR(VLOOKUP($AU3&"-"&$AV3,DECODE!$E$3:$F$21,2,FALSE),"?")) | AY3: =IF($AT3="","",IFERROR(VALUE(RIGHT($AT3,3)),"")) | AZ3: =IF($U3="","",IFERROR(IF(ISNUMBER($U3),$U3,DATEVALUE(TRIM($U3))),"")) | BA3: =IF($AZ3="","",IF(MONTH($AZ3)>=12,"Cold Winter",IF(MONTH($AZ3)>=10,"Post-Monsoon",IF(MONTH($AZ3)>=6,"Hot Humid",IF(MONTH($AZ3)>=3,"Hot Dry","Cold Winter"))))) | BB3: =IF($AU3="","",IFERROR(VLOOKUP($AU3,DECODE!$A$3:$C$8,2,FALSE),"?")) | BC3: =IF($P3="","",UPPER(TRIM(LEFT($P3&",",FIND(",",$P3&",")-1)))) | BD3: =IF($BC3="","",MID($BC3,4,FIND("~",SUBSTITUTE($BC3,"-","~",2))-4)) | BE3: =IF($BC3="","",MID($BC3,FIND("~",SUBSTITUTE($BC3,"-","~",2))+1,FIND("~",SUBSTITUTE($BC3,"-","~",3))-FIND("~",SUBSTITUTE($BC3,"-","~",2))-1)) | BF3: =IF($BD3="","",IFERROR(VLOOKUP($BD3,DECODE!$A$3:$C$8,3,FALSE),"?")) | BG3: =IF($BE3="","",IFERROR(VLOOKUP($BD3&"-"&$BE3,DECODE!$E$3:$F$21,2,FALSE),"?")) | BH3: =IF($BC3="","",IFERROR(VALUE(RIGHT($BC3,3)),"")) | BI3: =IF($V3="","",IFERROR(IF(ISNUMBER($V3),$V3,DATEVALUE(TRIM($V3))),"")) | BJ3: =IF($BI3="","",IF(MONTH($BI3)>=12,"Cold Winter",IF(MONTH($BI3)>=10,"Post-Monsoon",IF(MONTH($BI3)>=6,"Hot Humid",IF(MONTH($BI3)>=3,"Hot Dry","Cold Winter"))))) | BK3: =IF($BD3="","",IFERROR(VLOOKUP($BD3,DECODE!$A$3:$C$8,2,FALSE),"?")) | BL3: =IF($Q3="","",UPPER(TRIM(LEFT($Q3&",",FIND(",",$Q3&",")-1)))) | BM3: =IF($BL3="","",MID($BL3,4,FIND("~",SUBSTITUTE($BL3,"-","~",2))-4)) | BN3: =IF($BL3="","",MID($BL3,FIND("~",SUBSTITUTE($BL3,"-","~",2))+1,FIND("~",SUBSTITUTE($BL3,"-","~",3))-FIND("~",SUBSTITUTE($BL3,"-","~",2))-1)) | BO3: =IF($BM3="","",IFERROR(VLOOKUP($BM3,DECODE!$A$3:$C$8,3,FALSE),"?")) | BP3: =IF($BN3="","",IFERROR(VLOOKUP($BM3&"-"&$BN3,DECODE!$E$3:$F$21,2,FALSE),"?")) | BQ3: =IF($BL3="","",IFERROR(VALUE(RIGHT($BL3,3)),"")) | BR3: =IF($W3="","",IFERROR(IF(ISNUMBER($W3),$W3,DATEVALUE(TRIM($W3))),"")) | BS3: =IF($BR3="","",IF(MONTH($BR3)>=12,"Cold Winter",IF(MONTH($BR3)>=10,"Post-Monsoon",IF(MONTH($BR3)>=6,"Hot Humid",IF(MONTH($BR3)>=3,"Hot Dry","Cold Winter"))))) | BT3: =IF($BM3="","",IFERROR(VLOOKUP($BM3,DECODE!$A$3:$C$8,2,FALSE),"?")) | BU3: =IF($R3="","",UPPER(TRIM(LEFT($R3&",",FIND(",",$R3&",")-1)))) | BV3: =IF($BU3="","",MID($BU3,4,FIND("~",SUBSTITUTE($BU3,"-","~",2))-4)) | BW3: =IF($BU3="","",MID($BU3,FIND("~",SUBSTITUTE($BU3,"-","~",2))+1,FIND("~",SUBSTITUTE($BU3,"-","~",3))-FIND("~",SUBSTITUTE($BU3,"-","~",2))-1)) | BX3: =IF($BV3="","",IFERROR(VLOOKUP($BV3,DECODE!$A$3:$C$8,3,FALSE),"?")) | BY3: =IF($BW3="","",IFERROR(VLOOKUP($BV3&"-"&$BW3,DECODE!$E$3:$F$21,2,FALSE),"?")) | BZ3: =IF($BU3="","",IFERROR(VALUE(RIGHT($BU3,3)),"")) | CA3: =IF($X3="","",IFERROR(IF(ISNUMBER($X3),$X3,DATEVALUE(TRIM($X3))),"")) | CB3: =IF($CA3="","",IF(MONTH($CA3)>=12,"Cold Winter",IF(MONTH($CA3)>=10,"Post-Monsoon",IF(MONTH($CA3)>=6,"Hot Humid",IF(MONTH($CA3)>=3,"Hot Dry","Cold Winter"))))) | CC3: =IF($BV3="","",IFERROR(VLOOKUP($BV3,DECODE!$A$3:$C$8,2,FALSE),"?")) | CD3: =IF($S3="","",UPPER(TRIM(LEFT($S3&",",FIND(",",$S3&",")-1)))) | CE3: =IF($CD3="","",MID($CD3,4,FIND("~",SUBSTITUTE($CD3,"-","~",2))-4)) | CF3: =IF($CD3="","",MID($CD3,FIND("~",SUBSTITUTE($CD3,"-","~",2))+1,FIND("~",SUBSTITUTE($CD3,"-","~",3))-FIND("~",SUBSTITUTE($CD3,"-","~",2))-1)) | CG3: =IF($CE3="","",IFERROR(VLOOKUP($CE3,DECODE!$A$3:$C$8,3,FALSE),"?")) | CH3: =IF($CF3="","",IFERROR(VLOOKUP($CE3&"-"&$CF3,DECODE!$E$3:$F$21,2,FALSE),"?")) | CI3: =IF($CD3="","",IFERROR(VALUE(RIGHT($CD3,3)),"")) | CJ3: =IF($Y3="","",IFERROR(IF(ISNUMBER($Y3),$Y3,DATEVALUE(TRIM($Y3))),"")) | CK3: =IF($CJ3="","",IF(MONTH($CJ3)>=12,"Cold Winter",IF(MONTH($CJ3)>=10,"Post-Monsoon",IF(MONTH($CJ3)>=6,"Hot Humid",IF(MONTH($CJ3)>=3,"Hot Dry","Cold Winter"))))) | CL3: =IF($CE3="","",IFERROR(VLOOKUP($CE3,DECODE!$A$3:$C$8,2,FALSE),"?")) | CM3: =IF($AN3="","",AN3) | CN3: =IF($AO3="","",AO3) | CO3: =IF($AP3="","",AP3) | CP3: =IF($CM3="","",IF($CM3="Aloe Vera Gel","Aloe Vera Gel "&$CO3&"g",CN3&" "&$CO3&"g")) | CQ3: =IF($AT3="",0,1) | CR3: =IF($CQ3=0,"",AW3) | CS3: =IF($CQ3=0,"",AX3) | CT3: =IF($CQ3=0,"",AY3) | CU3: =IF($CR3="","",IF($CR3="Aloe Vera Gel","Aloe Vera Gel "&$CT3&"g",CS3&" "&$CT3&"g")) | CV3: =IF($CQ3=0,"",IF($CP3=$CU3,"Repeat Exact",IF($CT3>$CO3,"Upsized",IF($CT3<$CO3,"Downsized",IF($CM3<>$CR3,"Lateral","Same Size Diff Variant"))))) | CW3: =IF($CQ3=0,"",AZ3-AQ3) | CX3: =IF($CQ3=0,0,IF(CS3=CN3,1,0)) | CY3: =IF($CQ3=0,0,IF(CR3=CM3,1,0)) | CZ3: =IF($A3="","",IF(AND(IF(DASHBOARD!$C$4="All",TRUE,$CM3=DASHBOARD!$C$4),IF(DASHBOARD!$C$6="All",TRUE,$CP3=DASHBOARD!$C$6),IF(DASHBOARD!$C$8="All",TRUE,$AF3>=DASHBOARD!$C$8),IF(DASHBOARD!$C$10="All",TRUE,$AF3<=DASHBOARD!$C$10),IF(DASHBOARD!$C$12="All",TRUE,$AH3=VALUE(DASHBOARD!$C$12)),IF(DASHBOARD!$C$14="All",TRUE,$AJ3=DASHBOARD!$C$14)),1,0))
